Workbook
Name _Hlk187589439: 'CALCULATION SHEET'!#REF!
Name VerandaPriceMatrix: Table4[#All]
Name VerandaPriceMatrix: Table4[#All]

Sheet VerandaPriceMatrix
A1: Column1 | B1: NANTES | C1: BORDEAUX | D1: GIRONDE | E1: PROVENCE | F1: PROVENCE PLUS
A2: 4 x 2.5 | B2: 3369.6 | C2: 4008 | D2: 8416.8 | E2: 7887.6 | F2: x | I2: =INDEX(B2:F21,MATCH('PRESENTATION SHEET'!D12,VerandaPriceMatrix!A2:A21,0),MATCH('PRESENTATION SHEET'!D13,VerandaPriceMatrix!B1:F1,0)) -> 4735.2 | K2: =SUM(D2*1.75) -> 14729.4 | L2: =SUM(E2*1.75) -> 13803.3 | M2: =SUM(F2*1.8) -> #VALUE!
A3: 4 x 3 | B3: 3662.4 | C3: 4224 | D3: 8916.6 | E3: 8484 | F3: 12136.32 | K3: =SUM(D3*1.75) -> 15604.05 | L3: =SUM(E3*1.75) -> 14847 | M3: =SUM(F3*1.8) -> 21845.376
A4: 4 x 3.5 | B4: 3818.4 | C4: 4456.8 | D4: 9462.6 | E4: 9076.2 | F4: 13160.16 | K4: =SUM(D4*1.75) -> 16559.55 | L4: =SUM(E4*1.75) -> 15883.35 | M4: =SUM(F4*1.8) -> 23688.288
A5: 4 x 4 | B5: X | C5: 4862.4 | D5: 10403.4 | E5: 9735.6 | F5: 14253.12 | K5: =SUM(D5*1.75) -> 18205.95 | L5: =SUM(E5*1.75) -> 17037.3 | M5: =SUM(F5*1.8) -> 25655.616
A6: 4 x 6 | B6: X | C6: 5901.6 | D6: 12167.4 | E6: x | F6: x | K6: =SUM(D6*1.75) -> 21292.95 | L6: =SUM(E6*1.75) -> #VALUE! | M6: =SUM(F6*1.8) -> #VALUE!
A7: 5 x 2.5 | B7: 3717.6 | C7: 4435.2 | D7: 9399.6 | E7: 8845.2 | F7: x | K7: =SUM(D7*1.75) -> 16449.3 | L7: =SUM(E7*1.75) -> 15479.1 | M7: =SUM(F7*1.8) -> #VALUE!
A8: 5 x 3 | B8: 3931.2 | C8: 4735.2 | D8: 10122 | E8: 9378.6 | F8: 13682.88 | K8: =SUM(D8*1.75) -> 17713.5 | L8: =SUM(E8*1.75) -> 16412.55 | M8: =SUM(F8*1.8) -> 24629.184
A9: 5 x 3.5 | B9: 4168.8 | C9: 4965.6 | D9: 10630.2 | E9: 10033.8 | F9: 14883.84 | K9: =SUM(D9*1.75) -> 18602.85 | L9: =SUM(E9*1.75) -> 17559.15 | M9: =SUM(F9*1.8) -> 26790.912
A10: 5 x 4 | B10: X | C10: 5431.2 | D10: 11705.4 | E10: 11419.8 | F10: 16827.84 | K10: =SUM(D10*1.75) -> 20484.45 | L10: =SUM(E10*1.75) -> 19984.65 | M10: =SUM(F10*1.8) -> 30290.112
A11: 5 x 6 | B11: X | C11: 5858.4 | D11: 13860 | E11: x | F11: x | K11: =SUM(D11*1.75) -> 24255 | L11: =SUM(E11*1.75) -> #VALUE! | M11: =SUM(F11*1.8) -> #VALUE!
A12: 6 x 2.5 | B12: 4072.8 | C12: 6700.8 | D12: 10403.4 | E12: 9916.2 | F12: x | K12: =SUM(D12*1.75) -> 18205.95 | L12: =SUM(E12*1.75) -> 17353.35 | M12: =SUM(F12*1.8) -> #VALUE!
A13: 6 x 3 | B13: 4353.6 | C13: 4862.4 | D13: 11058.6 | E13: 10508.4 | F13: 15488.64 | K13: =SUM(D13*1.75) -> 19352.55 | L13: =SUM(E13*1.75) -> 18389.7 | M13: =SUM(F13*1.8) -> 27879.552
A14: 6 x 3.5 | B14: 4701.6 | C14: 5491.2 | D14: 11844 | E14: 11113.2 | F14: 16737.12 | K14: =SUM(D14*1.75) -> 20727 | L14: =SUM(E14*1.75) -> 19448.1 | M14: =SUM(F14*1.8) -> 30126.816
A15: 6 x 4 | B15: X | C15: 6055.2 | D15: 13158.6 | E15: 12511.8 | F15: 18802.08 | K15: =SUM(D15*1.75) -> 23027.55 | L15: =SUM(E15*1.75) -> 21895.65 | M15: =SUM(F15*1.8) -> 33843.744
A16: 6 x 6 | B16: X | C16: 7624.8 | D16: 15695.4 | E16: x | F16: x | K16: =SUM(D16*1.75) -> 27466.95 | L16: =SUM(E16*1.75) -> #VALUE! | M16: =SUM(F16*1.8) -> #VALUE!
A17: 7 x 2.5 | B17: X | C17: 5599.2 | D17: 11466 | E17: 10962 | F17: x | K17: =SUM(D17*1.75) -> 20065.5 | L17: =SUM(E17*1.75) -> 19183.5 | M17: =SUM(F17*1.8) -> #VALUE!
A18: 7 x 3 | B18: X | C18: 5894.4 | D18: 11923.8 | E18: 11587.8 | F18: x | K18: =SUM(D18*1.75) -> 20866.65 | L18: =SUM(E18*1.75) -> 20278.65 | M18: =SUM(F18*1.8) -> #VALUE!
A19: 7 x 3.5 | B19: X | C19: 6295.2 | D19: 12965.4 | E19: 12423.6 | F19: x | K19: =SUM(D19*1.75) -> 22689.45 | L19: =SUM(E19*1.75) -> 21741.3 | M19: =SUM(F19*1.8) -> #VALUE!
A20: 7 x 4 | B20: X | C20: 6919.2 | D20: 15082.2 | E20: 13830.6 | F20: x | K20: =SUM(D20*1.75) -> 26393.85 | L20: =SUM(E20*1.75) -> 24203.55 | M20: =SUM(F20*1.8) -> #VALUE!
A21: 7 x 6 | B21: X | C21: 9410.4 | D21: 17635.8 | E21: x | F21: x | K21: =SUM(D21*1.75) -> 30862.65 | L21: =SUM(E21*1.75) -> #VALUE! | M21: =SUM(F21*1.8) -> #VALUE!

Sheet CALCULATION SHEET
B2: VERANDA / PERGOLA COST SHEET
C3: DETAILS
B4: STYLE | C4: COLOUR | D4: QTY | E4: PRICE | I4: =VerandaPriceMatrix!I2 -> 4735.2
B5: WIDTH x PROJECTION (m) | D5: 1
B6: PRODUCTS
B7: ROOF | C7: COLOUR | D7: QTY | E7: PRICE | G7: ='PRESENTATION SHEET'!G14 -> 2 | H7: =IFERROR(VLOOKUP('PRESENTATION SHEET'!C14, Table6[#All], 4, FALSE), "") -> 60 | I7: =H7*G7 -> 120
B8: GLASS | E8: 50
B9: POLYCARBONATE | E9: 60
B10: GUTTER | C10: COLOUR | D10: QTY | E10: PRICE | G10: ='PRESENTATION SHEET'!G15 -> 1 | H10: =IFERROR(VLOOKUP('PRESENTATION SHEET'!C15, Table5[#All], 4, FALSE), "") -> 70 | I10: =G10*H10 -> 70
B11: ROUND | E11: 70
B12: CLASSIC | E12: 80
B13: POSTS | C13: COLOUR | D13: QTY | E13: PRICE | G13: ='PRESENTATION SHEET'!G16 -> 5 | H13: =IFERROR(VLOOKUP('PRESENTATION SHEET'!C16, Table7[#All], 4, FALSE), "") -> 250 | I13: =G13*H13 -> 1250
B14: SQUARE | E14: 250
B15: ROUNDED | E15: 300
B16: BASEPLATE | D16: ='PRESENTATION SHEET'!G17 -> 1 | E16: 69 | G16: ='PRESENTATION SHEET'!G17 -> 1 | H16: =IF('PRESENTATION SHEET'!D17="YES", E16, 0) -> 0 | I16: =H16*G16 -> 0
B17: CONCRETE | D17: ='PRESENTATION SHEET'!G18 -> 1 | E17: 250 | G17: ='PRESENTATION SHEET'!G18 -> 1 | H17: =IF('PRESENTATION SHEET'!D18="YES", E17, 0) -> 250 | I17: =H17*G17 -> 250
B18: LEFT RETURN | C18: COLOUR | D18: QTY | E18: PRICE | G18: ='PRESENTATION SHEET'!G21 -> 0 | H18: =IFERROR(VLOOKUP('PRESENTATION SHEET'!B21, Table1[#All], 4, FALSE), "") -> 500 | I18: =G18*H18 -> 0
B19: OPEN (NO SIDES) | E19: 500
B20: POLYCARBONATE KEYFRAME | E20: 300
B21: GLASS KEYFRAME | E21: 400
B22: POLYCARBONATE SIDEWALL | E22: 420
B23: ALUMINIUM SIDEWALL | E23: 700
B24: GLASS SLIDING DOORS | E24: 1300
B25: ROUND HANDLES or DOOR LOCKS | E25: 150
B26: OTHER - PLEASE SPECIFY | E26: 100
B27: FRONT | C27: COLOUR | D27: QTY | E27: PRICE | G27: ='PRESENTATION SHEET'!G24 -> 0 | H27: =IFERROR(VLOOKUP('PRESENTATION SHEET'!B24, Table2[#All], 4, FALSE), "") -> 500 | I27: =G27*H27 -> 0
B28: OPEN (NO SIDES) | E28: 500
B29: POLYCARBONATE KEYFRAME | E29: 300
B30: GLASS KEYFRAME | E30: 400
B31: POLYCARBONATE SIDEWALL | E31: 420
B32: ALUMINIUM SIDEWALL | E32: 700
B33: GLASS SLIDING DOORS | E33: 950
B34: ROUND HANDLES or DOOR LOCKS | E34: 150
B35: OTHER - PLEASE SPECIFY | E35: 100
B36: RIGHT RETURN | C36: COLOUR | D36: QTY | E36: PRICE | G36: ='PRESENTATION SHEET'!G27 -> 0 | H36: =IFERROR(VLOOKUP('PRESENTATION SHEET'!B27, Table3[#All], 4, FALSE), "") -> 500 | I36: =G36*H36 -> 0
B37: OPEN (NO SIDES) | E37: 500
B38: POLYCARBONATE KEYFRAME | E38: 300
B39: GLASS KEYFRAME | E39: 400
B40: POLYCARBONATE SIDEWALL | E40: 420
B41: ALUMINIUM SIDEWALL | E41: 700
...

Sheet PRESENTATION SHEET
B11: RANGE | N11: 45931
B12: WIDTH x PROJECTION (m) | D12: 5 x 3
B13: PRODUCTS | D13: BORDEAUX | F13: COLOUR | G13: QTY | I13: OTHERS | M13: COLOUR | N13: QTY
B14: ROOF | C14: POLYCARBONATE | F14: FRAME | G14: 2 | N14: 2
B15: GUTTER | C15: ROUND | G15: 1 | I15: keyframes above side doors
B16: POSTS | C16: SQUARE | F16: POLY. | G16: 5
C17: BASEPLATE | D17: NO | G17: 1
C18: CONCRETE | D18: YES | G18: 1
I19: TOTAL | M19: ='CALCULATION SHEET'!I51 -> 8225.2
B20: LEFT RETURN | G20: Qty
B21: OPEN (NO SIDES) | F21: metres | G21: 0
I22: CUSTOMER DETAILS
B23: FRONT | G23: Qty
B24: OPEN (NO SIDES) | F24: metres | G24: 0
B26: RIGHT RETURN | G26: Qty
B27: OPEN (NO SIDES) | F27: metres | G27: 0
